<?xml version="1.0" encoding="utf-8"?>
<!-- This URDF was automatically created by SolidWorks to URDF Exporter! Originally created by Stephen Brawner (brawner@gmail.com) 
     Commit Version: 1.6.0-4-g7f85cfe  Build Version: 1.6.7995.38578
     For more information, please see http://wiki.ros.org/sw_urdf_exporter -->
<robot
  name="drone_urdf">
  <link
    name="base_link">
    <inertial>
      <origin
        xyz="4.44064777294379E-16 -0.000401990618332168 8.22865101984521E-05"
        rpy="0 0 0" />
      <mass
        value="0.591785001312432" />
      <inertia
        ixx="0.000687815779136722"
        ixy="-8.71674991811453E-21"
        ixz="1.25469355670433E-20"
        iyy="0.000643842412936961"
        iyz="-3.22751861290967E-07"
        izz="0.00128478539822991" />
    </inertial>
    <visual>
      <origin
        xyz="0 0 0"
        rpy="0 0 0" />
      <geometry>
        <mesh
          filename="package://drone_urdf/meshes/base_link.STL" />
      </geometry>
      <material
        name="">
        <color
          rgba="0 0 0 1" />
      </material>
    </visual>
    <collision>
      <origin
        xyz="0 0 0"
        rpy="0 0 0" />
      <geometry>
        <mesh
          filename="package://drone_urdf/meshes/base_link.STL" />
      </geometry>
    </collision>
  </link>
  <link
    name="arm_link_pitch">
    <inertial>
      <origin
        xyz="-0.0276787855574874 0.00911709077232517 -0.00558440238980157"
        rpy="0 0 0" />
      <mass
        value="0.30558860051562" />
      <inertia
        ixx="0.000231244291658992"
        ixy="-4.93019763166128E-11"
        ixz="-3.31311957583298E-05"
        iyy="0.000281877615548305"
        iyz="8.74123284876137E-11"
        izz="0.000279381833421019" />
    </inertial>
    <visual>
      <origin
        xyz="0 0 0"
        rpy="0 0 0" />
      <geometry>
        <mesh
          filename="package://drone_urdf/meshes/arm_link_pitch.STL" />
      </geometry>
      <material
        name="">
        <color
          rgba="0.752941176470588 0.752941176470588 0.752941176470588 1" />
      </material>
    </visual>
    <collision>
      <origin
        xyz="0 0 0"
        rpy="0 0 0" />
      <geometry>
        <mesh
          filename="package://drone_urdf/meshes/arm_link_pitch.STL" />
      </geometry>
    </collision>
  </link>
  <joint
    name="arm_joint_pitch"
    type="continuous">
    <origin
      xyz="0 -0.00999999999999984 -0.106564971157456"
      rpy="0 0 0" />
    <parent
      link="base_link" />
    <child
      link="arm_link_pitch" />
    <axis
      xyz="0 -1 0" />
  </joint>
  <link
    name="arm_link_roll">
    <inertial>
      <origin
        xyz="-0.00169789176912286 -3.06699110552699E-15 -2.2065682614425E-15"
        rpy="0 0 0" />
      <mass
        value="0.000875819041355565" />
      <inertia
        ixx="4.34940605661605E-08"
        ixy="-2.94154456660538E-21"
        ixz="7.19733619713644E-21"
        iyy="2.28167020876951E-08"
        iyz="8.25355105256281E-23"
        izz="2.28167020877078E-08" />
    </inertial>
    <visual>
      <origin
        xyz="0 0 0"
        rpy="0 0 0" />
      <geometry>
        <mesh
          filename="package://drone_urdf/meshes/arm_link_roll.STL" />
      </geometry>
      <material
        name="">
        <color
          rgba="0.752941176470588 0.752941176470588 0.752941176470588 1" />
      </material>
    </visual>
    <collision>
      <origin
        xyz="0 0 0"
        rpy="0 0 0" />
      <geometry>
        <mesh
          filename="package://drone_urdf/meshes/arm_link_roll.STL" />
      </geometry>
    </collision>
  </link>
  <joint
    name="arm_joint_roll"
    type="continuous">
    <origin
      xyz="0.14395 0.00910000000000061 0"
      rpy="0 0 0" />
    <parent
      link="arm_link_pitch" />
    <child
      link="arm_link_roll" />
    <axis
      xyz="-1 0 0" />
  </joint>
</robot>